Workbook

Sheet Summary & Conclusion
B2: TITAN COMPANY LIMITED
B3: Financial Statement Analysis, 3-Statement Model, DCF Valuation & Peer Benchmarking
B4: Prepared by Abirami N | MBA Finance | Sep 2026
B6: EXECUTIVE SUMMARY
B7: This project evaluates Titan Company Limited's financial health and valuation over FY2022-FY2026 through four lenses: ratio-based risk analysis, a fully linked 3-statement model, a DCF valuation, and benchmarking against Kalyan Jewellers, its closest listed peer. The analysis finds a financially strong, well-run business whose current market valuation prices in growth and margin expansion well beyond what a standard 5-year explicit forecast can justify.
B9: KEY FIGURES (FY2026)
B10: Revenue | C10: ='Historical Financials'!$G$7 -> 87584
B11: Net Profit Margin | C11: ='Historical Financials'!$G$22/'Historical Financials'!$G$7 -> 0.057921538
B12: Return on Equity (ROE) | C12: ='Ratio Analysis'!$G$8 -> 0.32305929
B13: Debt-to-Equity | C13: ='Ratio Analysis'!$G$10 -> 1.9500096
B14: Interest Coverage Ratio | C14: ='Ratio Analysis'!$G$11 -> 7.4635593
B15: WACC (DCF) | C15: ='DCF Valuation'!$C$23 -> 0.10838389
B16: DCF Implied Share Price | C16: ='DCF Valuation'!$C$35 -> 235.63967
B17: Current Market Price | C17: ='Cover & Assumptions'!$C$9 -> 3951.4
B18: Implied Upside / (Downside) | C18: ='DCF Valuation'!$C$37 -> -0.94036552
B20: KEY FINDINGS
B21: 1. Rising leverage risk: Debt-to-Equity nearly doubled (0.78x → 1.95x, FY22-FY26) and Interest Coverage fell from 16.2x to 7.5x over the same period — debt is growing faster than the business's ability to service it comfortably, and this is the single clearest audit-style risk flag in the model.
B22: 2. Strong but volatile working capital intensity: Inventory Days rose to ~178 by FY26, and the increase-in-NWC ratio spiked to ~81% of incremental sales in FY25 alone — a heavy, uneven cash drag tied to gold stock build-up that's worth monitoring.
B23: 3. DCF suggests the stock is priced for a growth story beyond the base case: at a realistic WACC (10.8%, using market-value capital weights) and a conservative 15% growth fade, the DCF implies a share price of ~₹236 against a market price of ~₹3,951. Even the most optimistic sensitivity scenario (lower WACC, higher terminal growth) tops out around ₹476 — well below market. This is consistent with how high-quality "compounder" stocks typically trade, not a modeling error.
B24: 4. Justified premium over peers, but a wide one: Titan beats Kalyan Jewellers on every profitability metric (EBITDA margin, net margin, ROE) and the market rewards that with materially higher multiples (P/E 69x vs 45x). The gap in multiples is wider than the gap in fundamentals alone would suggest — the market is also paying for Titan's brand moat and category diversification (jewellery + watches + eyewear) that Kalyan doesn't have.
B26: HOW TO NAVIGATE THIS WORKBOOK
B27: Cover & Assumptions | C27: WACC and forecast assumptions — all editable (yellow cells)
B28: Historical Financials | C28: Titan's 3-statement model, FY2022-FY2026, fully linked
B29: Ratio Analysis | C29: 9 liquidity/profitability/solvency ratios with automated risk flags
B30: DCF Valuation | C30: 5-yr FCF projection, WACC build-up, terminal value, sensitivity table
B31: Peer Benchmarking | C31: Titan vs. Kalyan Jewellers on growth, margins, ROE, and multiples

Sheet Cover & Assumptions
B2: TITAN COMPANY LIMITED
B3: Financial Statement Analysis, 3-Statement Model & DCF Valuation
B5: All figures in ₹ Crores unless stated otherwise
B7: Data Source | C7: Screener.in (compiled from Titan Company Ltd. annual reports/filings), retrieved Sep 2026
B8: Period Covered | C8: FY2022 - FY2026 (5-year historicals)
B9: Current Market Price (as of data pull) | C9: 3951.4
B10: Shares Outstanding (Cr) | C10: 88.78
B13: KEY MODEL ASSUMPTIONS (edit yellow cells)
B14: Risk-free rate (10Y G-Sec) | C14: 0.068
B15: Equity risk premium | C15: 0.06
B16: Beta (Titan, 3Y) | C16: 0.75
B17: Cost of debt (pre-tax) | C17: 0.075
B18: Effective tax rate | C18: 0.26
B19: Terminal growth rate (g) | C19: 0.045
B20: Explicit forecast period (years) | C20: 5
B22: PROJECTION ASSUMPTIONS (DCF, edit yellow cells)
B23: Projected Revenue Growth (Yr1-5, flat) | C23: 0.15 | D23: Historical 4-yr CAGR was ~32%, but FY26 growth was likely inflated by the gold price rally; 15% is a more conservative, sustainable estimate — revisit this.
B24: Projected EBITDA Margin | C24: 0.098 | D24: 3-year historical average (FY24–FY26)
B25: D&A (% of Sales) | C25: 0.011 | D25: 5-year historical average
B26: Capex (% of Sales) | C26: 0.027 | D26: Derived: (ΔNet Block + Depreciation + ΔCWIP) / Sales, 4-yr average
B27: Increase in NWC (% of ΔSales) | C27: 0.2 | D27: Historical range was 16-31% in three of four years, with one outlier year (FY25) at ~81% (inventory build spike); using ~20% as a steadier baseline rather than the skewed 4-yr average

Sheet Historical Financials
B2: TITAN COMPANY LTD — HISTORICAL FINANCIAL STATEMENTS (₹ Cr)
B3: Source: Screener.in / Company Annual Reports, FY2022–FY2026
B5: INCOME STATEMENT
B6: Particulars | C6: FY2022 | D6: FY2023 | E6: FY2024 | F6: FY2025 | G6: FY2026
B7: Sales / Revenue | C7: 28799 | D7: 40575 | E7: 51084 | F7: 60456 | G7: 87584
B8: Raw Material Cost | C8: 26436 | D8: 32589 | E8: 42103 | F8: 55271 | G8: 80243
B9: Change in Inventory (per Screener convention) | C9: 4795 | D9: 2234 | E9: 2671 | F9: 7815 | G9: 9936
B10: Power & Fuel | C10: 45 | D10: 59 | E10: 71 | F10: 78 | G10: 87
B11: Other Mfg. Expenses | C11: 183 | D11: 225 | E11: 286 | F11: 326 | G11: 375
B12: Employee Cost | C12: 1356 | D12: 1656 | E12: 1875 | F12: 2164 | G12: 2692
B13: Selling & Admin Expenses | C13: 1697 | D13: 2715 | E13: 3249 | F13: 3494 | G13: 4185
B14: Other Expenses | C14: 533 | D14: 683 | E14: 879 | F14: 1244 | G14: 1581 | I14: Itemized lines above are as reported by Screener; Total Expenses below is derived from PBT (see note)
B15: Other Income | C15: 177 | D15: 306 | E15: 534 | F15: 487 | G15: 450
B16: Depreciation | C16: 399 | D16: 441 | E16: 584 | F16: 693 | G16: 826
B17: Interest | C17: 218 | D17: 300 | E17: 619 | F17: 953 | G17: 1180
B18: Profit Before Tax | C18: 2904 | D18: 4447 | E18: 4623 | F18: 4535 | G18: 6801 | I18: Hardcoded from Screener (reliable, audited figure)
B19: Operating Profit (EBITDA) [derived] | C19: =C18-C15+C16+C17 -> 3344 | D19: =D18-D15+D16+D17 -> 4882 | E19: =E18-E15+E16+E17 -> 5292 | F19: =F18-F15+F16+F17 -> 5694 | G19: =G18-G15+G16+G17 -> 8357 | I19: Formula: PBT − Other Income + Depreciation + Interest
B20: Total Expenses [derived] | C20: =C7-C19 -> 25455 | D20: =D7-D19 -> 35693 | E20: =E7-E19 -> 45792 | F20: =F7-F19 -> 54762 | G20: =G7-G19 -> 79227 | I20: Formula: Sales − Operating Profit (plug)
B21: Tax | C21: 706 | D21: 1173 | E21: 1127 | F21: 1198 | G21: 1728
B22: Net Profit | C22: =C18-C21 -> 2198 | D22: =D18-D21 -> 3274 | E22: =E18-E21 -> 3496 | F22: =F18-F21 -> 3337 | G22: =G18-G21 -> 5073
B24: BALANCE SHEET
B25: Particulars | C25: FY2022 | D25: FY2023 | E25: FY2024 | F25: FY2025 | G25: FY2026
B26: Equity Share Capital | C26: 89 | D26: 89 | E26: 89 | F26: 89 | G26: 89
B27: Reserves & Surplus | C27: 9214 | D27: 11762 | E27: 9304 | F27: 11535 | G27: 15614
B28: Borrowings | C28: 7275 | D28: 9367 | E28: 15528 | F28: 20777 | G28: 30621
B29: Other Liabilities | C29: 4610 | D29: 5802 | E29: 6626 | F29: 8244 | G29: 14237
B30: Total Liabilities & Equity | C30: =C26+C27+C28+C29 -> 21188 | D30: =D26+D27+D28+D29 -> 27020 | E30: =E26+E27+E28+E29 -> 31547 | F30: =F26+F27+F28+F29 -> 40645 | G30: =G26+G27+G28+G29 -> 60561
B31: Net Block (Fixed Assets) | C31: 2544 | D31: 2998 | E31: 3709 | F31: 4062 | G31: 6878
B32: Capital Work in Progress | C32: 85 | D32: 144 | E32: 97 | F32: 105 | G32: 163
B33: Investments | C33: 294 | D33: 2515 | E33: 2345 | F33: 1988 | G33: 3506
B34: Other Assets (incl. Inventory, Receivables, Cash) | C34: 18265 | D34: 21363 | E34: 25396 | F34: 34490 | G34: 50014
B35: Total Assets | C35: =C31+C32+C33+C34 -> 21188 | D35: =D31+D32+D33+D34 -> 27020 | E35: =E31+E32+E33+E34 -> 31547 | F35: =F31+F32+F33+F34 -> 40645 | G35: =G31+G32+G33+G34 -> 60561
B36: Balance Check (Assets − Liabilities) | C36: =C35-C30 -> 0 | D36: =D35-D30 -> 0 | E36: =E35-E30 -> 0 | F36: =F35-F30 -> 0 | G36: =G35-G30 -> 0
B38: Receivables | C38: 565 | D38: 674 | E38: 1018 | F38: 1068 | G38: 916
B39: Inventory | C39: 13609 | D39: 16584 | E39: 19051 | F39: 28184 | G39: 42743
B40: Cash & Bank | C40: 1573 | D40: 1343 | E40: 1526 | F40: 1584 | G40: 1917
B42: CASH FLOW STATEMENT
B43: Particulars | C43: FY2022 | D43: FY2023 | E43: FY2024 | F43: FY2025 | G43: FY2026
B44: Cash from Operating Activity | C44: -724 | D44: 1370 | E44: 1695 | F44: -541 | G44: 5590
B45: Cash from Investing Activity | C45: 1165 | D45: -1814 | E45: -189 | F45: 546 | G45: -2965
...

Sheet Ratio Analysis
B2: TITAN COMPANY LTD — RATIO & RISK ANALYSIS
B3: Liquidity, profitability & solvency ratios, FY2022–FY2026, with risk commentary
B5: RATIO | C5: FY2022 | D5: FY2023 | E5: FY2024 | F5: FY2025 | G5: FY2026 | I5: Trend / Risk Flag
B6: Operating Profit Margin (OPM) | C6: ='Historical Financials'!C19/'Historical Financials'!C7 -> 0.11611514 | D6: ='Historical Financials'!D19/'Historical Financials'!D7 -> 0.12032039 | E6: ='Historical Financials'!E19/'Historical Financials'!E7 -> 0.10359408 | F6: ='Historical Financials'!F19/'Historical Financials'!F7 -> 0.0941842 | G6: ='Historical Financials'!G19/'Historical Financials'!G7 -> 0.095416971 | I6: =IF(C6<F6,"Margin compressing — investigate cost drivers","Stable/improving") -> Stable/improving
B7: Net Profit Margin | C7: ='Historical Financials'!C22/'Historical Financials'!C7 -> 0.076322095 | D7: ='Historical Financials'!D22/'Historical Financials'!D7 -> 0.08069008 | E7: ='Historical Financials'!E22/'Historical Financials'!E7 -> 0.068436301 | F7: ='Historical Financials'!F22/'Historical Financials'!F7 -> 0.055197168 | G7: ='Historical Financials'!G22/'Historical Financials'!G7 -> 0.057921538
B8: Return on Equity (ROE) | C8: ='Historical Financials'!C22/('Historical Financials'!C26+'Historical Financials'!C27) -> 0.23626787 | D8: ='Historical Financials'!D22/('Historical Financials'!D26+'Historical Financials'!D27) -> 0.27626361 | E8: ='Historical Financials'!E22/('Historical Financials'!E26+'Historical Financials'!E27) -> 0.37219206 | F8: ='Historical Financials'!F22/('Historical Financials'!F26+'Historical Financials'!F27) -> 0.28707846 | G8: ='Historical Financials'!G22/('Historical Financials'!G26+'Historical Financials'!G27) -> 0.32305929
B9: Return on Capital Employed (ROCE) | C9: ='Historical Financials'!C19/('Historical Financials'!C26+'Historical Financials'!C27+'Historical Financials'!C28) -> 0.20171311 | D9: ='Historical Financials'!D19/('Historical Financials'!D26+'Historical Financials'!D27+'Historical Financials'!D28) -> 0.23008766 | E9: ='Historical Financials'!E19/('Historical Financials'!E26+'Historical Financials'!E27+'Historical Financials'!E28) -> 0.21235103 | F9: ='Historical Financials'!F19/('Historical Financials'!F26+'Historical Financials'!F27+'Historical Financials'!F28) -> 0.17573532 | G9: ='Historical Financials'!G19/('Historical Financials'!G26+'Historical Financials'!G27+'Historical Financials'!G28) -> 0.18040325
B10: Debt-to-Equity Ratio | C10: ='Historical Financials'!C28/('Historical Financials'!C26+'Historical Financials'!C27) -> 0.7820058 | D10: ='Historical Financials'!D28/('Historical Financials'!D26+'Historical Financials'!D27) -> 0.79039743 | E10: ='Historical Financials'!E28/('Historical Financials'!E26+'Historical Financials'!E27) -> 1.653146 | F10: ='Historical Financials'!F28/('Historical Financials'!F26+'Historical Financials'!F27) -> 1.7874226 | G10: ='Historical Financials'!G28/('Historical Financials'!G26+'Historical Financials'!G27) -> 1.9500096 | I10: =IF(G9>C9*1.3,"Leverage rising materially — flag for review","Within normal range") -> Within normal range
B11: Interest Coverage Ratio | C11: =('Historical Financials'!C19+'Historical Financials'!C15)/'Historical Financials'!C17 -> 16.151376 | D11: =('Historical Financials'!D19+'Historical Financials'!D15)/'Historical Financials'!D17 -> 17.293333 | E11: =('Historical Financials'!E19+'Historical Financials'!E15)/'Historical Financials'!E17 -> 9.4119548 | F11: =('Historical Financials'!F19+'Historical Financials'!F15)/'Historical Financials'!F17 -> 6.4858342 | G11: =('Historical Financials'!G19+'Historical Financials'!G15)/'Historical Financials'!G17 -> 7.4635593 | I11: =IF(G10<C10*0.7,"Coverage weakening — debt servicing risk","Adequate coverage") -> Adequate coverage
B12: Inventory Days | C12: ='Historical Financials'!C39/'Historical Financials'!C7*365 -> 172.48116 | D12: ='Historical Financials'!D39/'Historical Financials'!D7*365 -> 149.18447 | E12: ='Historical Financials'!E39/'Historical Financials'!E7*365 -> 136.12119 | F12: ='Historical Financials'!F39/'Historical Financials'!F7*365 -> 170.15945 | G12: ='Historical Financials'!G39/'Historical Financials'!G7*365 -> 178.12837 | I12: =IF(G11>C11*1.2,"Inventory building up faster than sales — investigate","Stable turnover") -> Stable turnover
B13: Debtor Days | C13: ='Historical Financials'!C38/'Historical Financials'!C7*365 -> 7.1608389 | D13: ='Historical Financials'!D38/'Historical Financials'!D7*365 -> 6.063093 | E13: ='Historical Financials'!E38/'Historical Financials'!E7*365 -> 7.2737061 | F13: ='Historical Financials'!F38/'Historical Financials'!F7*365 -> 6.4479952 | G13: ='Historical Financials'!G38/'Historical Financials'!G7*365 -> 3.8173639
B14: Asset Turnover Ratio | C14: ='Historical Financials'!C7/'Historical Financials'!C35 -> 1.3592128 | D14: ='Historical Financials'!D7/'Historical Financials'!D35 -> 1.5016654 | E14: ='Historical Financials'!E7/'Historical Financials'!E35 -> 1.6192982 | F14: ='Historical Financials'!F7/'Historical Financials'!F35 -> 1.4874154 | G14: ='Historical Financials'!G7/'Historical Financials'!G35 -> 1.4462113
B15: Cash & Bank (% of Total Assets) | C15: ='Historical Financials'!C40/'Historical Financials'!C35 -> 0.074240136 | D15: ='Historical Financials'!D40/'Historical Financials'!D35 -> 0.049703923 | E15: ='Historical Financials'!E40/'Historical Financials'!E35 -> 0.04837227 | F15: ='Historical Financials'!F40/'Historical Financials'!F35 -> 0.038971583 | G15: ='Historical Financials'!G40/'Historical Financials'!G35 -> 0.031654035
B18: AUDIT-STYLE RISK NOTES
B19: 1. Borrowings grew from ₹7,275 Cr (FY22) to ₹30,621 Cr (FY26), a ~4.2x increase — review Debt-to-Equity and Interest Coverage trend above before concluding on solvency risk.
B20: 2. Inventory nearly tripled (₹13,609 Cr → ₹42,743 Cr) over the same period — check whether this tracks revenue growth (~3x) or signals a slower-moving stock build-up.
B21: 3. Cash from Operating Activity was negative in FY22 and FY25 — worth investigating working-capital swings behind these two years specifically.
B22: 4. Fill in your own observations here once you review the trend/flag column above — this is where your analytical judgment (the actual audit-relevant skill) goes.

Sheet DCF Valuation
B2: TITAN COMPANY LTD — DCF VALUATION
B3: 5-year FCF projection, WACC-discounted, with terminal value (Gordon Growth)
B5: FREE CASH FLOW PROJECTION (₹ Cr)
B6: Particulars | C6: FY2027E | D6: FY2028E | E6: FY2029E | F6: FY2030E | G6: FY2031E
B7: Revenue | C7: ='Historical Financials'!$G$7*(1+'Cover & Assumptions'!$C$23) -> 100721.6 | D7: =C7*(1+'Cover & Assumptions'!$C$23) -> 115829.84 | E7: =D7*(1+'Cover & Assumptions'!$C$23) -> 133204.32 | F7: =E7*(1+'Cover & Assumptions'!$C$23) -> 153184.96 | G7: =F7*(1+'Cover & Assumptions'!$C$23) -> 176162.71
B8: EBITDA (at target margin) | C8: =C7*'Cover & Assumptions'!$C$24 -> 9870.7168 | D8: =D7*'Cover & Assumptions'!$C$24 -> 11351.324 | E8: =E7*'Cover & Assumptions'!$C$24 -> 13054.023 | F8: =F7*'Cover & Assumptions'!$C$24 -> 15012.126 | G8: =G7*'Cover & Assumptions'!$C$24 -> 17263.945
B9: Less: D&A | C9: =C7*'Cover & Assumptions'!$C$25 -> 1107.9376 | D9: =D7*'Cover & Assumptions'!$C$25 -> 1274.1282 | E9: =E7*'Cover & Assumptions'!$C$25 -> 1465.2475 | F9: =F7*'Cover & Assumptions'!$C$25 -> 1685.0346 | G9: =G7*'Cover & Assumptions'!$C$25 -> 1937.7898
B10: EBIT | C10: =C8-C9 -> 8762.7792 | D10: =D8-D9 -> 10077.196 | E10: =E8-E9 -> 11588.775 | F10: =F8-F9 -> 13327.092 | G10: =G8-G9 -> 15326.156
B11: Less: Tax on EBIT | C11: =C10*'Cover & Assumptions'!$C$18 -> 2278.3226 | D11: =D10*'Cover & Assumptions'!$C$18 -> 2620.071 | E11: =E10*'Cover & Assumptions'!$C$18 -> 3013.0816 | F11: =F10*'Cover & Assumptions'!$C$18 -> 3465.0439 | G11: =G10*'Cover & Assumptions'!$C$18 -> 3984.8005
B12: NOPAT | C12: =C10-C11 -> 6484.4566 | D12: =D10-D11 -> 7457.1251 | E12: =E10-E11 -> 8575.6939 | F12: =F10-F11 -> 9862.0479 | G12: =G10-G11 -> 11341.355
B13: Add: D&A | C13: =C9 -> 1107.9376 | D13: =D9 -> 1274.1282 | E13: =E9 -> 1465.2475 | F13: =F9 -> 1685.0346 | G13: =G9 -> 1937.7898
B14: Less: Capex | C14: =C7*'Cover & Assumptions'!$C$26 -> 2719.4832 | D14: =D7*'Cover & Assumptions'!$C$26 -> 3127.4057 | E14: =E7*'Cover & Assumptions'!$C$26 -> 3596.5165 | F14: =F7*'Cover & Assumptions'!$C$26 -> 4135.994 | G14: =G7*'Cover & Assumptions'!$C$26 -> 4756.3931
B15: Less: Increase in NWC | C15: =(C7-'Historical Financials'!$G$7)*'Cover & Assumptions'!$C$27 -> 2627.52 | D15: =(D7-C7)*'Cover & Assumptions'!$C$27 -> 3021.648 | E15: =(E7-D7)*'Cover & Assumptions'!$C$27 -> 3474.8952 | F15: =(F7-E7)*'Cover & Assumptions'!$C$27 -> 3996.1295 | G15: =(G7-F7)*'Cover & Assumptions'!$C$27 -> 4595.5489
B16: Free Cash Flow (FCF) | C16: =C12+C13-C14-C15 -> 2245.391 | D16: =D12+D13-D14-D15 -> 2582.1997 | E16: =E12+E13-E14-E15 -> 2969.5296 | F16: =F12+F13-F14-F15 -> 3414.959 | G16: =G12+G13-G14-G15 -> 3927.2029
B18: WACC CALCULATION
B19: Cost of Equity (CAPM) = Rf + Beta × ERP | C19: ='Cover & Assumptions'!$C$14+'Cover & Assumptions'!$C$16*'Cover & Assumptions'!$C$15 -> 0.113
B20: Post-tax Cost of Debt = Kd × (1 - Tax) | C20: ='Cover & Assumptions'!$C$17*(1-'Cover & Assumptions'!$C$18) -> 0.0555
B21: Weight of Equity = Market Cap / (Market Cap + Borrowings) | C21: =('Cover & Assumptions'!$C$9*'Cover & Assumptions'!$C$10)/('Cover & Assumptions'!$C$9*'Cover & Assumptions'!$C$10+'Historical Financials'!$G$28) -> 0.91971974
B22: Weight of Debt | C22: =1-C21 -> 0.080280255
B23: WACC | C23: =C21*C19+C22*C20 -> 0.10838389
B25: VALUATION
B26: Discount Factor | C26: =1/(1+$C$23)^1 -> 0.90221449 | D26: =1/(1+$C$23)^2 -> 0.81399098 | E26: =1/(1+$C$23)^3 -> 0.73439446 | F26: =1/(1+$C$23)^4 -> 0.66258132 | G26: =1/(1+$C$23)^5 -> 0.59779047
B27: PV of FCF | C27: =C16*C26 -> 2025.8243 | D27: =D16*D26 -> 2101.8872 | E27: =E16*E26 -> 2180.8061 | F27: =F16*F26 -> 2262.6881 | G27: =G16*G26 -> 2347.6445
B28: Sum of PV of FCF (Yr1-5) | C28: =SUM(C27:G27) -> 10918.85
B29: Terminal Value (Yr5) = FCF5 × (1+g) / (WACC - g) | C29: =G16*(1+'Cover & Assumptions'!$C$19)/($C$23-'Cover & Assumptions'!$C$19) -> 64747.167
B30: PV of Terminal Value | C30: =C29*G26 -> 38705.239
B31: Enterprise Value | C31: =C28+C30 -> 49624.09
B32: Less: Net Debt (FY26 Borrowings − Cash & Bank) | C32: ='Historical Financials'!$G$28-'Historical Financials'!$G$40 -> 28704
B33: Equity Value | C33: =C31-C32 -> 20920.09
B34: Shares Outstanding (Cr) | C34: ='Cover & Assumptions'!$C$10 -> 88.78
B35: Implied Share Price | C35: =C33/C34 -> 235.63967
B36: Current Market Price | C36: ='Cover & Assumptions'!$C$9 -> 3951.4
B37: Implied Upside / (Downside) | C37: =C35/C36-1 -> -0.94036552
B40: SENSITIVITY: IMPLIED SHARE PRICE (WACC vs Terminal Growth)
B41: WACC \ Terminal g | C41: ='Cover & Assumptions'!$C$19+(-0.01) -> 0.035 | D41: ='Cover & Assumptions'!$C$19+(-0.005) -> 0.04 | E41: ='Cover & Assumptions'!$C$19+(0) -> 0.045 | F41: ='Cover & Assumptions'!$C$19+(0.005) -> 0.05 | G41: ='Cover & Assumptions'!$C$19+(0.01) -> 0.055
B42: =$C$23+(-0.01) -> 0.098383885 | C42: =((C$16/(1+$B42)^1+D$16/(1+$B42)^2+E$16/(1+$B42)^3+F$16/(1+$B42)^4+G$16/(1+$B42)^5+(G$16*(1+C$41)/($B42-C$41))/(1+$B42)^5)-$C$32)/$C$34 -> 254.96948 | D42: =((C$16/(1+$B42)^1+D$16/(1+$B42)^2+E$16/(1+$B42)^3+F$16/(1+$B42)^4+G$16/(1+$B42)^5+(G$16*(1+D$41)/($B42-D$41))/(1+$B42)^5)-$C$32)/$C$34 -> 296.03239 | E42: =((C$16/(1+$B42)^1+D$16/(1+$B42)^2+E$16/(1+$B42)^3+F$16/(1+$B42)^4+G$16/(1+$B42)^5+(G$16*(1+E$41)/($B42-E$41))/(1+$B42)^5)-$C$32)/$C$34 -> 344.78731 | F42: =((C$16/(1+$B42)^1+D$16/(1+$B42)^2+E$16/(1+$B42)^3+F$16/(1+$B42)^4+G$16/(1+$B42)^5+(G$16*(1+F$41)/($B42-F$41))/(1+$B42)^5)-$C$32)/$C$34 -> 403.61891 | G42: =((C$16/(1+$B42)^1+D$16/(1+$B42)^2+E$16/(1+$B42)^3+F$16/(1+$B42)^4+G$16/(1+$B42)^5+(G$16*(1+G$41)/($B42-G$41))/(1+$B42)^5)-$C$32)/$C$34 -> 476.01121
B43: =$C$23+(-0.005) -> 0.10338389 | C43: =((C$16/(1+$B43)^1+D$16/(1+$B43)^2+E$16/(1+$B43)^3+F$16/(1+$B43)^4+G$16/(1+$B43)^5+(G$16*(1+C$41)/($B43-C$41))/(1+$B43)^5)-$C$32)/$C$34 -> 210.77055 | D43: =((C$16/(1+$B43)^1+D$16/(1+$B43)^2+E$16/(1+$B43)^3+F$16/(1+$B43)^4+G$16/(1+$B43)^5+(G$16*(1+D$41)/($B43-D$41))/(1+$B43)^5)-$C$32)/$C$34 -> 245.19754 | E43: =((C$16/(1+$B43)^1+D$16/(1+$B43)^2+E$16/(1+$B43)^3+F$16/(1+$B43)^4+G$16/(1+$B43)^5+(G$16*(1+E$41)/($B43-E$41))/(1+$B43)^5)-$C$32)/$C$34 -> 285.52119 | F43: =((C$16/(1+$B43)^1+D$16/(1+$B43)^2+E$16/(1+$B43)^3+F$16/(1+$B43)^4+G$16/(1+$B43)^5+(G$16*(1+F$41)/($B43-F$41))/(1+$B43)^5)-$C$32)/$C$34 -> 333.39836 | G43: =((C$16/(1+$B43)^1+D$16/(1+$B43)^2+E$16/(1+$B43)^3+F$16/(1+$B43)^4+G$16/(1+$B43)^5+(G$16*(1+G$41)/($B43-G$41))/(1+$B43)^5)-$C$32)/$C$34 -> 391.1708
B44: =$C$23+(0) -> 0.10838389 | C44: =((C$16/(1+$B44)^1+D$16/(1+$B44)^2+E$16/(1+$B44)^3+F$16/(1+$B44)^4+G$16/(1+$B44)^5+(G$16*(1+C$41)/($B44-C$41))/(1+$B44)^5)-$C$32)/$C$34 -> 172.627 | D44: =((C$16/(1+$B44)^1+D$16/(1+$B44)^2+E$16/(1+$B44)^3+F$16/(1+$B44)^4+G$16/(1+$B44)^5+(G$16*(1+D$41)/($B44-D$41))/(1+$B44)^5)-$C$32)/$C$34 -> 201.8297 | E44: =((C$16/(1+$B44)^1+D$16/(1+$B44)^2+E$16/(1+$B44)^3+F$16/(1+$B44)^4+G$16/(1+$B44)^5+(G$16*(1+E$41)/($B44-E$41))/(1+$B44)^5)-$C$32)/$C$34 -> 235.63967 | F44: =((C$16/(1+$B44)^1+D$16/(1+$B44)^2+E$16/(1+$B44)^3+F$16/(1+$B44)^4+G$16/(1+$B44)^5+(G$16*(1+F$41)/($B44-F$41))/(1+$B44)^5)-$C$32)/$C$34 -> 275.24061 | G44: =((C$16/(1+$B44)^1+D$16/(1+$B44)^2+E$16/(1+$B44)^3+F$16/(1+$B44)^4+G$16/(1+$B44)^5+(G$16*(1+G$41)/($B44-G$41))/(1+$B44)^5)-$C$32)/$C$34 -> 322.2597
B45: =$C$23+(0.005) -> 0.11338389 | C45: =((C$16/(1+$B45)^1+D$16/(1+$B45)^2+E$16/(1+$B45)^3+F$16/(1+$B45)^4+G$16/(1+$B45)^5+(G$16*(1+C$41)/($B45-C$41))/(1+$B45)^5)-$C$32)/$C$34 -> 139.37933 | D45: =((C$16/(1+$B45)^1+D$16/(1+$B45)^2+E$16/(1+$B45)^3+F$16/(1+$B45)^4+G$16/(1+$B45)^5+(G$16*(1+D$41)/($B45-D$41))/(1+$B45)^5)-$C$32)/$C$34 -> 164.40185 | E45: =((C$16/(1+$B45)^1+D$16/(1+$B45)^2+E$16/(1+$B45)^3+F$16/(1+$B45)^4+G$16/(1+$B45)^5+(G$16*(1+E$41)/($B45-E$41))/(1+$B45)^5)-$C$32)/$C$34 -> 193.08349 | F45: =((C$16/(1+$B45)^1+D$16/(1+$B45)^2+E$16/(1+$B45)^3+F$16/(1+$B45)^4+G$16/(1+$B45)^5+(G$16*(1+F$41)/($B45-F$41))/(1+$B45)^5)-$C$32)/$C$34 -> 226.2902 | G45: =((C$16/(1+$B45)^1+D$16/(1+$B45)^2+E$16/(1+$B45)^3+F$16/(1+$B45)^4+G$16/(1+$B45)^5+(G$16*(1+G$41)/($B45-G$41))/(1+$B45)^5)-$C$32)/$C$34 -> 265.18456
B46: =$C$23+(0.01) -> 0.11838389 | C46: =((C$16/(1+$B46)^1+D$16/(1+$B46)^2+E$16/(1+$B46)^3+F$16/(1+$B46)^4+G$16/(1+$B46)^5+(G$16*(1+C$41)/($B46-C$41))/(1+$B46)^5)-$C$32)/$C$34 -> 110.14616 | D46: =((C$16/(1+$B46)^1+D$16/(1+$B46)^2+E$16/(1+$B46)^3+F$16/(1+$B46)^4+G$16/(1+$B46)^5+(G$16*(1+D$41)/($B46-D$41))/(1+$B46)^5)-$C$32)/$C$34 -> 131.77661 | E46: =((C$16/(1+$B46)^1+D$16/(1+$B46)^2+E$16/(1+$B46)^3+F$16/(1+$B46)^4+G$16/(1+$B46)^5+(G$16*(1+E$41)/($B46-E$41))/(1+$B46)^5)-$C$32)/$C$34 -> 156.35464 | F46: =((C$16/(1+$B46)^1+D$16/(1+$B46)^2+E$16/(1+$B46)^3+F$16/(1+$B46)^4+G$16/(1+$B46)^5+(G$16*(1+F$41)/($B46-F$41))/(1+$B46)^5)-$C$32)/$C$34 -> 184.5268 | G46: =((C$16/(1+$B46)^1+D$16/(1+$B46)^2+E$16/(1+$B46)^3+F$16/(1+$B46)^4+G$16/(1+$B46)^5+(G$16*(1+G$41)/($B46-G$41))/(1+$B46)^5)-$C$32)/$C$34 -> 217.14365
...

Sheet Peer Benchmarking
B2: TITAN vs. KALYAN JEWELLERS — PEER BENCHMARKING (₹ Cr)
B3: Source: Screener.in, FY2022–FY2026 | Peer selected for jewellery-segment comparability
B5: KALYAN JEWELLERS — HISTORICAL DATA (₹ Cr)
B6: Particulars | C6: FY2022 | D6: FY2023 | E6: FY2024 | F6: FY2025 | G6: FY2026
B7: Sales | C7: 10817.93 | D7: 14071.45 | E7: 18515.55 | F7: 25045.07 | G7: 35742.86
B8: Other Income | C8: 38.29 | D8: 4.64 | E8: 106.44 | F8: 140.18 | G8: 162.25
B9: Depreciation | C9: 231.58 | D9: 244.58 | E9: 274.3 | F9: 342.72 | G9: 422.86
B10: Interest | C10: 360.37 | D10: 353.48 | E10: 378.59 | F10: 422.37 | G10: 499.48
B11: Profit Before Tax | C11: 298.85 | D11: 571.53 | E11: 788.83 | F11: 959.6 | G11: 1801.99
B12: Tax | C12: 74.82 | D12: 139.59 | E12: 192.54 | F12: 245.43 | G12: 451.59
B13: Net Profit | C13: =C11-C12 -> 224.03 | D13: =D11-D12 -> 431.94 | E13: =E11-E12 -> 596.29 | F13: =F11-F12 -> 714.17 | G13: =G11-G12 -> 1350.4
B14: Operating Profit (EBITDA) [derived] | C14: =C11-C8+C9+C10 -> 852.51 | D14: =D11-D8+D9+D10 -> 1164.95 | E14: =E11-E8+E9+E10 -> 1335.28 | F14: =F11-F8+F9+F10 -> 1584.51 | G14: =G11-G8+G9+G10 -> 2562.08
B15: Equity Share Capital | C15: 1030.05 | D15: 1030.05 | E15: 1030.05 | F15: 1031.44 | G15: 1032.74
B16: Reserves | C16: 2106.97 | D16: 2604.66 | E16: 3159 | F16: 3772.14 | G16: 5275.97
B17: Borrowings | C17: 4029.32 | D17: 4295.49 | E17: 4494.95 | F17: 4959.36 | G17: 6117.34
B18: Receivables | C18: 119.47 | D18: 244.23 | E18: 328.32 | F18: 399.92 | G18: 866.55
B19: Inventory | C19: 5794.26 | D19: 7013.88 | E19: 8297.57 | F19: 9681.11 | G19: 14174.58
B20: Total Assets | C20: 8945.15 | D20: 10712.95 | E20: 12817.73 | F20: 15125.95 | G20: 20716.64
B21: Current Market Price (₹) | G21: 582.85
B22: Shares Outstanding (Cr) | G22: 103.27
B24: COMPARATIVE METRICS — FY2026
B25: Metric | C25: Titan | D25: Kalyan Jewellers
B26: Revenue (FY26, ₹ Cr) | C26: ='Historical Financials'!$G$7 -> 87584 | D26: =$G$7 -> 35742.86
B27: 4-Yr Revenue CAGR (FY22-FY26) | C27: =('Historical Financials'!$G$7/'Historical Financials'!$C$7)^(1/4)-1 -> 0.32057126 | D27: =($G$7/$C$7)^(1/4)-1 -> 0.34822161
B28: EBITDA (Operating Profit) Margin | C28: ='Historical Financials'!$G$19/'Historical Financials'!$G$7 -> 0.095416971 | D28: =$G$14/$G$7 -> 0.07168089
B29: Net Profit Margin | C29: ='Historical Financials'!$G$22/'Historical Financials'!$G$7 -> 0.057921538 | D29: =$G$13/$G$7 -> 0.037780972
B30: Return on Equity (ROE) | C30: ='Historical Financials'!$G$22/('Historical Financials'!$G$26+'Historical Financials'!$G$27) -> 0.32305929 | D30: =$G$13/($G$15+$G$16) -> 0.21405327
B31: Market Capitalization (₹ Cr) | C31: ='Cover & Assumptions'!$C$9*'Cover & Assumptions'!$C$10 -> 350805.29 | D31: =$G$21*$G$22 -> 60190.92
B32: P/E Ratio (Price / EPS) | C32: =('Cover & Assumptions'!$C$9*'Cover & Assumptions'!$C$10)/'Historical Financials'!$G$22 -> 69.151447 | D32: =($G$21*$G$22)/$G$13 -> 44.57266
B33: EV/EBITDA | C33: =('Cover & Assumptions'!$C$9*'Cover & Assumptions'!$C$10+'Historical Financials'!$G$28-'Historical Financials'!$G$40)/'Historical Financials'!$G$19 -> 45.412145 | D33: =($G$21*$G$22+$G$17)/$G$14 -> 25.880636
B35: OBSERVATIONS
B36: 1. Profitability: Titan converts revenue to profit more efficiently than Kalyan at every level — EBITDA margin (9.5% vs 7.2%) and net margin (5.8% vs 3.8%) are both wider, despite Titan being ~2.5x larger by revenue. This suggests scale and brand strength (multi-category: jewellery, watches, eyewear) give Titan real operating leverage that a single-category peer doesn't have.
B37: 2. Growth: Kalyan actually grew slightly faster (34.8% vs 32.1% 4-yr CAGR), though both figures are inflated by the FY26 gold price rally across the sector, so this gap is not a reliable signal of who is winning market share on its own.
B38: 3. Capital efficiency: Titan's ROE (32.3%) is meaningfully higher than Kalyan's (21.4%), reinforcing that Titan generates more profit per rupee of shareholder capital — a key reason it commands a valuation premium.
B39: 4. Valuation: The market prices Titan at a large premium to Kalyan on every multiple — P/E 69.2x vs 44.6x, EV/EBITDA 45.4x vs 25.9x. Part of this premium is justified by Titan's superior margins and ROE, but the size of the gap (roughly 1.5-1.7x on both multiples) is wider than the margin/ROE gap alone would suggest, implying the market is also paying for Titan's brand moat and category diversification.
B40: 5. Read together with the DCF: even Titan's premium over its closest peer looks rich against a standard 5-year DCF (implied price ~₹236 vs market price ~₹3,951). This points to one conclusion — Titan is a fundamentally stronger business than Kalyan, but at the current price, the market is pricing in a very long runway of continued margin expansion and growth that goes beyond what a base-case explicit forecast captures. This is a normal feature of high-quality "compounder" stocks, not a sign of a flawed model.
